Workbook

Sheet Cover Page ---->
Q24: August 2017

Sheet Key Assumptions & Drivers
B1: Name
B2: Key Assumptions & Drivers
B4: Revenue & Traffic Assumptions
B5: Traffic Conversion
D6: 2023 | E6: 2024 | F6: 2025 | G6: 2026 | H6: 2027 | I6: 2028 | J6: 2029
B7: Daily Traffic Counts: | D7: 11458 | E7: =D7*((1+$D$8)^3) -> 12159.321 | F7: =E7*(1+$D$8) -> 12402.508 | G7: =F7*(1+$D$8) -> 12650.558 | H7: =G7*(1+$D$8) -> 12903.569 | I7: =H7*(1+$D$8) -> 13161.64 | J7: =I7*(1+$D$8) -> 13424.873
B8: Annual Traffic Escalator | D8: 0.02
B9: Days Operational / Month | D9: 26
B10: Discounts/Coupons | D10: 0.1
B11: CC Processing Fees | D11: 0.02
E13: Var Chem | F13: % of
B14: Pricing Options | D14: Price | E14: Costs | F14: Washes
B15: Bronze | D15: 9 | E15: 0.58 | F15: 0.5
B16: Silver | D16: 12 | E16: 1 | F16: 0.1
B17: Gold | D17: 18 | E17: 1.5 | F17: 0.1
B18: Best In Class | D18: 23 | E18: 2.09 | F18: 0.3
B19: Wtd Average / Car | D19: =SUMPRODUCT(D15:D18,F15:F18)*(1-D10) -> 12.96 | E19: =SUMPRODUCT(E15:E18,F15:F18) -> 1.167 | H19: =D19*2.5 -> 32.4 | I19: =E19*2.5 -> 2.9175 | J19: =H19-I19 -> 29.4825
B20: Gold Unlimited | D20: 19.99 | E20: =E17 -> 1.5 | F20: 0.7
B21: BIC Unlimited | D21: 40 | E21: =E18 -> 2.09 | F21: =1-F20 -> 0.3
B22: Wtd Average (Price / Var Chem Cost) | D22: =SUMPRODUCT(D20:D21,$F$20:$F$21) -> 25.993 | E22: =SUMPRODUCT(E20:E21,$F$20:$F$21) -> 1.677 | H22: =D22 -> 25.993 | I22: =E22*2.5 -> 4.1925 | J22: =H22-I22 -> 21.8005
B24: Average Wash / Month | D24: 2.5
E26: 45139 | F26: =EDATE(E26,1) -> 45170 | G26: =EDATE(F26,1) -> 45200 | H26: =EDATE(G26,1) -> 45231 | I26: =EDATE(H26,1) -> 45261 | J26: =EDATE(I26,1) -> 45292 | K26: =EDATE(J26,1) -> 45323 | L26: =EDATE(K26,1) -> 45352 | M26: =EDATE(L26,1) -> 45383 | ... O26: =EDATE(N26,1) -> 45444 | P26: =EDATE(O26,12) -> 45809 | Q26: =EDATE(P26,12) -> 46174 | R26: =EDATE(Q26,12) -> 46539 | S26: =EDATE(R26,12) -> 46905
B27: New Net Subscribers | D27: % | E27: 100 | F27: 100 | G27: 100 | H27: 100 | I27: 100 | J27: 100 | K27: 100 | L27: 100 | M27: 100 | N27: 100 | O27: 100 | P27: 100 | Q27: =P28*$D$29 -> 96 | R27: =Q28*$D$29 -> 103.68 | S27: =R28*$D$29 -> 111.9744
B28: Total Net Subscribers | E28: =E27 -> 100 | F28: =E28+F27 -> 200 | G28: =F28+G27 -> 300 | H28: =G28+H27 -> 400 | I28: =H28+I27 -> 500 | J28: =I28+J27 -> 600 | K28: =J28+K27 -> 700 | L28: =K28+L27 -> 800 | M28: =L28+M27 -> 900 | ... S28: =R28+S27 -> 1511.6544
B29: Annual Growth Rate 2019+ | D29: 0.08
D32: 6 Months
B33: Imputed Capture: | D33: Construction | E33: 45139 | F33: =EDATE(E33,1) -> 45170 | G33: =EDATE(F33,1) -> 45200 | H33: =EDATE(G33,1) -> 45231 | I33: =EDATE(H33,1) -> 45261 | J33: =EDATE(I33,1) -> 45292 | K33: =EDATE(J33,1) -> 45323 | L33: =EDATE(K33,1) -> 45352 | M33: =EDATE(L33,1) -> 45383 | ... O33: =EDATE(N33,1) -> 45444 | P33: =EDATE(O33,12) -> 45809 | Q33: =EDATE(P33,12) -> 46174 | R33: =EDATE(Q33,12) -> 46539 | S33: =EDATE(R33,12) -> 46905
B34: Capture Rate | D34: 0 | E34: 0.02 | F34: 0.02 | G34: 0.02 | H34: 0.02 | I34: 0.02 | J34: 0.02 | K34: 0.02 | L34: 0.02 | M34: 0.02 | N34: 0.02 | O34: 0.02 | P34: 0.02 | Q34: 0.02 | R34: 0.02 | S34: 0.02
B35: Cars Captured Daily | D35: =D34*$E$7 -> 0 | E35: =E34*$E$7 -> 243.18643 | F35: =F34*$E$7 -> 243.18643 | G35: =G34*$E$7 -> 243.18643 | H35: =H34*$E$7 -> 243.18643 | I35: =I34*$E$7 -> 243.18643 | J35: =J34*$F$7 -> 248.05015 | K35: =K34*$F$7 -> 248.05015 | L35: =L34*$F$7 -> 248.05015 | M35: =M34*$F$7 -> 248.05015 | N35: =N34*$F$7 -> 248.05015 | O35: =O34*$F$7 -> 248.05015 | P35: =P34*$G$7 -> 253.01116 | Q35: =Q34*$H$7 -> 258.07138 | R35: =R34*$I$7 -> 263.23281 | S35: =S34*$J$7 -> 268.49746
B36: Cars Captured by Period | D36: =D35*$D$9 -> 0 | E36: =E35*$D$9 -> 6322.8471 | F36: =F35*$D$9 -> 6322.8471 | G36: =G35*$D$9 -> 6322.8471 | H36: =H35*$D$9 -> 6322.8471 | I36: =I35*$D$9 -> 6322.8471 | J36: =J35*$D$9 -> 6449.304 | K36: =K35*$D$9 -> 6449.304 | ... O36: =O35*$D$9 -> 6449.304 | P36: =P35*$D$9*12 -> 78939.481 | Q36: =Q35*$D$9*12 -> 80518.271 | R36: =R35*$D$9*12 -> 82128.636 | S36: =S35*$D$9*12 -> 83771.209
B37: Unlimited Cars by Period | D37: 0 | E37: =E28*$D$24 -> 250 | F37: =F28*$D$24 -> 500 | G37: =G28*$D$24 -> 750 | H37: =H28*$D$24 -> 1000 | I37: =I28*$D$24 -> 1250 | J37: =J28*$D$24 -> 1500 | K37: =K28*$D$24 -> 1750 | L37: =L28*$D$24 -> 2000 | ... O37: =O28*$D$24 -> 2750 | P37: =P28*$D$24*12 -> 36000 | Q37: =Q28*$D$24*12 -> 38880 | R37: =R28*$D$24*12 -> 41990.4 | S37: =S28*$D$24*12 -> 45349.632
B38: Total Cars Washed | D38: =SUM(D36:D37) -> 0 | E38: =SUM(E36:E37) -> 6572.8471 | F38: =SUM(F36:F37) -> 6822.8471 | G38: =SUM(G36:G37) -> 7072.8471 | H38: =SUM(H36:H37) -> 7322.8471 | I38: =SUM(I36:I37) -> 7572.8471 | J38: =SUM(J36:J37) -> 7949.304 | K38: =SUM(K36:K37) -> 8199.304 | ... S38: =SUM(S36:S37) -> 129120.84
B39: Implied Capture Rate | E39: =E38/($E$7*$D$9) -> 0.020790783 | F39: =F38/($E$7*$D$9) -> 0.021581566 | G39: =G38/($E$7*$D$9) -> 0.022372349 | H39: =H38/($E$7*$D$9) -> 0.023163132 | I39: =I38/($E$7*$D$9) -> 0.023953915 | J39: =J38/($F$7*$D$9) -> 0.024651665 | K39: =K38/($F$7*$D$9) -> 0.025426942 | L39: =L38/($F$7*$D$9) -> 0.02620222 | M39: =M38/($F$7*$D$9) -> 0.026977497 | N39: =N38/($F$7*$D$9) -> 0.027752775 | O39: =O38/($F$7*$D$9) -> 0.028528052 | P39: =P38/($G$7*$D$9*12) -> 0.029120911 | Q39: =Q38/($H$7*$D$9*12) -> 0.029657435 | R39: =R38/($I$7*$D$9*12) -> 0.03022552 | S39: =S38/($J$7*$D$9*12) -> 0.030827021
P40: =P38/300/10/60 -> 0.63855267
B41: Revenue Mix
B42: Cars Captured | E42: =E36/E38 -> 0.96196473 | F42: =F36/F38 -> 0.92671681 | G42: =G36/G38 -> 0.89396066 | H42: =H36/H38 -> 0.86344109 | I42: =I36/I38 -> 0.83493658 | J42: =J36/J38 -> 0.81130423 | K42: =K36/K38 -> 0.78656725 | L42: =L36/L38 -> 0.76329411 | ... S42: =S36/S38 -> 0.64878147
B43: Unlimited Plan | E43: =1-E42 -> 0.038035268 | F43: =1-F42 -> 0.07328319 | G43: =1-G42 -> 0.10603934 | H43: =1-H42 -> 0.13655891 | I43: =1-I42 -> 0.16506342 | J43: =1-J42 -> 0.18869577 | K43: =1-K42 -> 0.21343275 | L43: =1-L42 -> 0.23670589 | ... S43: =1-S42 -> 0.35121853
B44: Implied Average Variable Cost | E44: =(E42*$E$19)+(E43*$E$22) -> 1.186398 | F44: =(F42*$E$19)+(F43*$E$22) -> 1.2043744 | G44: =(G42*$E$19)+(G43*$E$22) -> 1.2210801 | H44: =(H42*$E$19)+(H43*$E$22) -> 1.236645 | I44: =(I42*$E$19)+(I43*$E$22) -> 1.2511823 | J44: =(J42*$E$19)+(J43*$E$22) -> 1.2632348 | K44: =(K42*$E$19)+(K43*$E$22) -> 1.2758507 | L44: =(L42*$E$19)+(L43*$E$22) -> 1.28772 | ... S44: =(S42*$E$19)+(S43*$E$22) -> 1.3461215
B46: Operating Expenses
B47: Total Variable Costs (Excl Chemicals) | D47: =SUM(D48:D52) -> 2.28
...

Sheet Summary P&L
B2: STATEMENT OF OPERATIONS
D5: 6 Months
C6: Note | D6: Construction | E6: 45139 | F6: 45170 | G6: 45200 | H6: 45231 | I6: 45261 | J6: 45292 | K6: 45323 | L6: 45352 | M6: 45383 | N6: 45413 | O6: 45444 | P6: Year 1 | Q6: Year 2 | R6: Year 3 | S6: Year 4 | T6: Year 5
D7: (est.) | E7: (est.) | F7: (est.) | G7: (est.) | H7: (est.) | I7: (est.) | J7: (est.) | K7: (est.) | L7: (est.) | M7: (est.) | N7: (est.) | O7: (est.) | P7: (est.) | Q7: (est.) | R7: (est.) | S7: (est.) | T7: (est.)
B9: Revenue | C9: A. | D9: ='Notes A&B - Revenue & COGS'!E24 -> 0 | E9: ='Notes A&B - Revenue & COGS'!F24 -> 82852.53 | F9: ='Notes A&B - Revenue & COGS'!G24 -> 85399.844 | G9: ='Notes A&B - Revenue & COGS'!H24 -> 87947.158 | H9: ='Notes A&B - Revenue & COGS'!I24 -> 90494.472 | I9: ='Notes A&B - Revenue & COGS'!J24 -> 93041.786 | J9: ='Notes A&B - Revenue & COGS'!K24 -> 97195.204 | K9: ='Notes A&B - Revenue & COGS'!L24 -> 99742.518 | ... O9: ='Notes A&B - Revenue & COGS'!P24 -> 109931.77 | P9: =SUM(D9:O9) -> 1061116.7 | Q9: ='Notes A&B - Revenue & COGS'!R24 -> 1369407.8 | R9: ='Notes A&B - Revenue & COGS'!S24 -> 1418804.7 | S9: ='Notes A&B - Revenue & COGS'!T24 -> 1470950.3 | T9: ='Notes A&B - Revenue & COGS'!U24 -> 1526040.4
B10: % Change | D10: =_xlfn.IFERROR((D9-C9)/C9,"NM") -> NM | E10: =_xlfn.IFERROR((E9-D9)/D9,"NM") -> NM | F10: =_xlfn.IFERROR((F9-E9)/E9,"NM") -> 0.030745157 | G10: =_xlfn.IFERROR((G9-F9)/F9,"NM") -> 0.029828087 | H10: =_xlfn.IFERROR((H9-G9)/G9,"NM") -> 0.028964142 | I10: =_xlfn.IFERROR((I9-H9)/H9,"NM") -> 0.028148835 | J10: =_xlfn.IFERROR((J9-I9)/I9,"NM") -> 0.044640355 | K10: =_xlfn.IFERROR((K9-J9)/J9,"NM") -> 0.026208227 | ... O10: =_xlfn.IFERROR((O9-N9)/N9,"NM") -> 0.02372144 | Q10: =(Q9-((P9/COUNTIF(D9:O9,">0"))*12))/((P9/COUNTIF(D9:O9,">0"))*12) -> 0.18298999 | R10: =_xlfn.IFERROR((R9-Q9)/Q9,"NM") -> 0.03607176 | S10: =_xlfn.IFERROR((S9-R9)/R9,"NM") -> 0.036753184 | T10: =_xlfn.IFERROR((T9-S9)/S9,"NM") -> 0.037452021
B12: COGS | C12: B. | D12: ='Notes A&B - Revenue & COGS'!E46+'Notes A&B - Revenue & COGS'!E39 -> 22620.923 | E12: ='Notes A&B - Revenue & COGS'!F46+'Notes A&B - Revenue & COGS'!F39 -> 42035.011 | F12: ='Notes A&B - Revenue & COGS'!G46+'Notes A&B - Revenue & COGS'!G39 -> 42664.921 | G12: ='Notes A&B - Revenue & COGS'!H46+'Notes A&B - Revenue & COGS'!H39 -> 43294.83 | H12: ='Notes A&B - Revenue & COGS'!I46+'Notes A&B - Revenue & COGS'!I39 -> 43924.74 | I12: ='Notes A&B - Revenue & COGS'!J46+'Notes A&B - Revenue & COGS'!J39 -> 44554.65 | J12: ='Notes A&B - Revenue & COGS'!K46+'Notes A&B - Revenue & COGS'!K39 -> 45438.806 | K12: ='Notes A&B - Revenue & COGS'!L46+'Notes A&B - Revenue & COGS'!L39 -> 46068.716 | ... O12: ='Notes A&B - Revenue & COGS'!P46+'Notes A&B - Revenue & COGS'!P39 -> 48588.355 | P12: =SUM(D12:O12) -> 521176.56 | Q12: ='Notes A&B - Revenue & COGS'!R46+'Notes A&B - Revenue & COGS'!R39 -> 610846.56 | R12: ='Notes A&B - Revenue & COGS'!S46+'Notes A&B - Revenue & COGS'!S39 -> 627861.82 | S12: ='Notes A&B - Revenue & COGS'!T46+'Notes A&B - Revenue & COGS'!T39 -> 645874 | T12: ='Notes A&B - Revenue & COGS'!U46+'Notes A&B - Revenue & COGS'!U39 -> 664951.85
B14: Gross Profit | D14: =D9-D12 -> -22620.923 | E14: =E9-E12 -> 40817.519 | F14: =F9-F12 -> 42734.923 | G14: =G9-G12 -> 44652.328 | H14: =H9-H12 -> 46569.732 | I14: =I9-I12 -> 48487.136 | J14: =J9-J12 -> 51756.398 | K14: =K9-K12 -> 53673.803 | ... T14: =T9-T12 -> 861088.53
B15: Margin % | D15: =_xlfn.IFERROR(D14/D9,"NA") -> NA | E15: =_xlfn.IFERROR(E14/E9,"NA") -> 0.49265266 | F15: =_xlfn.IFERROR(F14/F9,"NA") -> 0.50040985 | G15: =_xlfn.IFERROR(G14/G9,"NA") -> 0.50771769 | H15: =_xlfn.IFERROR(H14/H9,"NA") -> 0.51461411 | I15: =_xlfn.IFERROR(I14/I9,"NA") -> 0.5211329 | J15: =_xlfn.IFERROR(J14/J9,"NA") -> 0.53249951 | K15: =_xlfn.IFERROR(K14/K9,"NA") -> 0.5381236 | ... T15: =_xlfn.IFERROR(T14/T9,"NA") -> 0.56426327
B17: SG&A | C17: C. | D17: ='Note C - SG&A'!D27 -> 25000 | E17: ='Note C - SG&A'!E27 -> 41292.604 | F17: ='Note C - SG&A'!F27 -> 18845.354 | G17: ='Note C - SG&A'!G27 -> 18898.104 | H17: ='Note C - SG&A'!H27 -> 18950.854 | I17: ='Note C - SG&A'!I27 -> 19003.604 | J17: ='Note C - SG&A'!J27 -> 19083.036 | K17: ='Note C - SG&A'!K27 -> 19135.786 | ... O17: ='Note C - SG&A'!O27 -> 19346.786 | P17: =SUM(D17:O17) -> 257279.99 | Q17: ='Note C - SG&A'!Q27 -> 242757.67 | R17: ='Note C - SG&A'!R27 -> 254214.16 | S17: ='Note C - SG&A'!S27 -> 266687.81 | T17: ='Note C - SG&A'!T27 -> 280273.45
B18: SG&A % | D18: =_xlfn.IFERROR(D17/D9,0) -> 0 | E18: =_xlfn.IFERROR(E17/E9,0) -> 0.49838676 | F18: =_xlfn.IFERROR(F17/F9,0) -> 0.220672 | G18: =_xlfn.IFERROR(G17/G9,0) -> 0.21488021 | H18: =_xlfn.IFERROR(H17/H9,0) -> 0.20941449 | I18: =_xlfn.IFERROR(I17/I9,0) -> 0.20424806 | J18: =_xlfn.IFERROR(J17/J9,0) -> 0.19633722 | K18: =_xlfn.IFERROR(K17/K9,0) -> 0.19185185 | ... T18: =_xlfn.IFERROR(T17/T9,0) -> 0.18366057
B20: EBIT (Operating Profit) | D20: =D14-D17 -> -47620.923 | E20: =E14-E17 -> -475.08504 | F20: =F14-F17 -> 23889.569 | G20: =G14-G17 -> 25754.223 | H20: =H14-H17 -> 27618.878 | I20: =I14-I17 -> 29483.532 | J20: =J14-J17 -> 32673.362 | K20: =K14-K17 -> 34538.016 | ... T20: =T14-T17 -> 580815.09
B21: Margin % | D21: =_xlfn.IFERROR(D20/D9,0) -> 0 | E21: =_xlfn.IFERROR(E20/E9,0) -> -0.0057341042 | F21: =_xlfn.IFERROR(F20/F9,0) -> 0.27973786 | G21: =_xlfn.IFERROR(G20/G9,0) -> 0.29283747 | H21: =_xlfn.IFERROR(H20/H9,0) -> 0.30519961 | I21: =_xlfn.IFERROR(I20/I9,0) -> 0.31688485 | J21: =_xlfn.IFERROR(J20/J9,0) -> 0.33616228 | K21: =_xlfn.IFERROR(K20/K9,0) -> 0.34627175 | ... T21: =_xlfn.IFERROR(T20/T9,0) -> 0.3806027
B23: Depr & Adjustments | C23: D. | D23: ='Note D - PPE'!D43 -> 18002.381 | E23: ='Note D - PPE'!E43 -> 18031.971 | F23: ='Note D - PPE'!F43 -> 18032.881 | G23: ='Note D - PPE'!G43 -> 18033.791 | H23: ='Note D - PPE'!H43 -> 18034.7 | I23: ='Note D - PPE'!I43 -> 18035.61 | J23: ='Note D - PPE'!J43 -> 18037.094 | K23: ='Note D - PPE'!K43 -> 18038.003 | ... O23: ='Note D - PPE'!O43 -> 18041.642 | P23: =SUM(D23:O23) -> 216407.54 | Q23: ='Note D - PPE'!Q43 -> 227766.35 | R23: ='Note D - PPE'!R43 -> 228189.75 | S23: ='Note D - PPE'!S43 -> 228636.72 | T23: ='Note D - PPE'!T43 -> 229108.92
B25: Adj. EBITDA | D25: =D20+D23 -> -29618.542 | E25: =E20+E23 -> 17556.886 | F25: =F20+F23 -> 41922.45 | G25: =G20+G23 -> 43788.014 | H25: =H20+H23 -> 45653.578 | I25: =I20+I23 -> 47519.142 | J25: =J20+J23 -> 50710.455 | K25: =K20+K23 -> 52576.019 | ... T25: =T20+T23 -> 809924
B26: Margin % | D26: =_xlfn.IFERROR(D25/D9,"NA") -> NA | E26: =_xlfn.IFERROR(E25/E9,"NA") -> 0.21190525 | F26: =_xlfn.IFERROR(F25/F9,"NA") -> 0.4908961 | G26: =_xlfn.IFERROR(G25/G9,"NA") -> 0.49789004 | H26: =_xlfn.IFERROR(H25/H9,"NA") -> 0.50449024 | I26: =_xlfn.IFERROR(I25/I9,"NA") -> 0.51072904 | J26: =_xlfn.IFERROR(J25/J9,"NA") -> 0.52173825 | K26: =_xlfn.IFERROR(K25/K9,"NA") -> 0.52711743 | ... T26: =_xlfn.IFERROR(T25/T9,"NA") -> 0.53073563
B28: Interest | C28: E. | D28: =SUM('Note E - Loan Amortization'!I20:I25) -> 108337.47 | E28: ='Note E - Loan Amortization'!I21 -> 18109.17 | F28: ='Note E - Loan Amortization'!I22 -> 18074.136 | G28: ='Note E - Loan Amortization'!I23 -> 18038.899 | H28: ='Note E - Loan Amortization'!I24 -> 18003.455 | I28: ='Note E - Loan Amortization'!I25 -> 17967.805 | J28: ='Note E - Loan Amortization'!I26 -> 17931.947 | K28: ='Note E - Loan Amortization'!I27 -> 17895.88 | L28: ='Note E - Loan Amortization'!I28 -> 17859.602 | M28: ='Note E - Loan Amortization'!I29 -> 17823.113 | N28: ='Note E - Loan Amortization'!I30 -> 17786.411 | O28: ='Note E - Loan Amortization'!I31 -> 17749.495 | P28: =SUM(D28:O28) -> 305577.38 | Q28: ='Note E - Loan Amortization'!M43 -> 210034.82 | R28: ='Note E - Loan Amortization'!M55 -> 204299.04 | S28: ='Note E - Loan Amortization'!M67 -> 198148.62 | T28: ='Note E - Loan Amortization'!M79 -> 191553.58
B29: Fees | D29: =('Key Assumptions & Drivers'!$D$100/2) -> 1555.2 | E29: =('Key Assumptions & Drivers'!$D$100/12) -> 259.2 | F29: =('Key Assumptions & Drivers'!$D$100/12) -> 259.2 | G29: =('Key Assumptions & Drivers'!$D$100/12) -> 259.2 | H29: =('Key Assumptions & Drivers'!$D$100/12) -> 259.2 | I29: =('Key Assumptions & Drivers'!$D$100/12) -> 259.2 | J29: =('Key Assumptions & Drivers'!$D$100/12) -> 259.2 | K29: =('Key Assumptions & Drivers'!$D$100/12) -> 259.2 | L29: =('Key Assumptions & Drivers'!$D$100/12) -> 259.2 | ... O29: =('Key Assumptions & Drivers'!$D$100/12) -> 259.2 | P29: =SUM(D29:O29) -> 4406.4 | Q29: ='Key Assumptions & Drivers'!$D$100 -> 3110.4 | R29: ='Key Assumptions & Drivers'!$D$100 -> 3110.4 | S29: ='Key Assumptions & Drivers'!$D$100 -> 3110.4 | T29: ='Key Assumptions & Drivers'!$D$100 -> 3110.4
B31: Earnings before Taxes | D31: =D20-D28-D29 -> -157513.59 | E31: =E20-E28-E29 -> -18843.455 | F31: =F20-F28-F29 -> 5556.2329 | G31: =G20-G28-G29 -> 7456.1249 | H31: =H20-H28-H29 -> 9356.2225 | I31: =I20-I28-I29 -> 11256.527 | J31: =J20-J28-J29 -> 14482.215 | K31: =K20-K28-K29 -> 16382.936 | ... T31: =T20-T28-T29 -> 386151.11
B33: Taxes - No Corp. Tax | C33: n/a | D33: 0 | E33: 0 | F33: 0 | G33: 0 | H33: 0 | I33: 0 | J33: 0 | K33: 0 | L33: 0 | M33: 0 | N33: 0 | O33: 0 | P33: 0 | Q33: 0 | R33: 0 | S33: 0 | T33: 0
B35: Net Income/(Loss) | D35: =D20-D28-D29-D33 -> -157513.59 | E35: =E20-E28-E29-E33 -> -18843.455 | F35: =F20-F28-F29-F33 -> 5556.2329 | G35: =G20-G28-G29-G33 -> 7456.1249 | H35: =H20-H28-H29-H33 -> 9356.2225 | I35: =I20-I28-I29-I33 -> 11256.527 | J35: =J20-J28-J29-J33 -> 14482.215 | K35: =K20-K28-K29-K33 -> 16382.936 | ... T35: =T20-T28-T29-T33 -> 386151.11
B36: Margin % | D36: =_xlfn.IFERROR(D35/D9,"NA") -> NA | E36: =_xlfn.IFERROR(E35/E9,"NA") -> -0.22743367 | F36: =_xlfn.IFERROR(F35/F9,"NA") -> 0.065061394 | G36: =_xlfn.IFERROR(G35/G9,"NA") -> 0.0847796 | H36: =_xlfn.IFERROR(H35/H9,"NA") -> 0.10338999 | I36: =_xlfn.IFERROR(I35/I9,"NA") -> 0.12098356 | J36: =_xlfn.IFERROR(J35/J9,"NA") -> 0.14900133 | K36: =_xlfn.IFERROR(K35/K9,"NA") -> 0.16425228 | ... T36: =_xlfn.IFERROR(T35/T9,"NA") -> 0.25304121

Sheet Balance Sheet
B2: BALANCE SHEETS
E5: 6 Months
C6: Note | D6: Opening | E6: Construction | F6: 45139 | G6: 43344 | H6: 43374 | I6: 43405 | J6: 43435 | K6: 43466 | L6: 43497 | M6: 43525 | N6: 43556 | O6: 43586 | P6: 43617 | Q6: Year 1 | R6: 43983 | S6: 44348 | T6: 44713 | U6: 45078
F7: (est.) | G7: (est.) | H7: (est.) | I7: (est.) | J7: (est.) | K7: (est.) | L7: (est.) | M7: (est.) | N7: (est.) | O7: (est.) | P7: (est.) | Q7: (est.) | R7: (est.) | S7: (est.) | T7: (est.) | U7: (est.)
B8: Current Assets
B9: Cash | D9: ='Cash Flow'!F29 -> 4075792 | E9: ='Cash Flow'!G29 -> 238484.07 | F9: ='Cash Flow'!H29 -> 229440.48 | G9: ='Cash Flow'!I29 -> 244686.04 | H9: ='Cash Flow'!J29 -> 261720.74 | I9: ='Cash Flow'!K29 -> 280544.59 | J9: ='Cash Flow'!L29 -> 301157.58 | K9: ='Cash Flow'!M29 -> 324837.28 | ... U9: ='Cash Flow'!W29 -> 1727068.7
B10: AR
B11: Inventory
B12: Prepaids
B13: Total Current Assets | D13: =SUM(D9:D12) -> 4075792 | E13: =SUM(E9:E12) -> 238484.07 | F13: =SUM(F9:F12) -> 229440.48 | G13: =SUM(G9:G12) -> 244686.04 | H13: =SUM(H9:H12) -> 261720.74 | I13: =SUM(I9:I12) -> 280544.59 | J13: =SUM(J9:J12) -> 301157.58 | K13: =SUM(K9:K12) -> 324837.28 | ... U13: =SUM(U9:U12) -> 1727068.7
B15: PP&E | E15: ='Note D - PPE'!D28 -> 3663000 | F15: ='Note D - PPE'!E28 -> 3665485.6 | G15: ='Note D - PPE'!F28 -> 3668047.6 | H15: ='Note D - PPE'!G28 -> 3670686 | I15: ='Note D - PPE'!H28 -> 3673400.8 | J15: ='Note D - PPE'!I28 -> 3676192.1 | K15: ='Note D - PPE'!J28 -> 3679107.9 | L15: ='Note D - PPE'!K28 -> 3682100.2 | ... U15: ='Note D - PPE'!T28 -> 4041945.7
B16: Less Acc Dep | E16: =-'Note D - PPE'!D44 -> -18002.381 | F16: =-'Note D - PPE'!E44 -> -36034.352 | G16: =-'Note D - PPE'!F44 -> -54067.233 | H16: =-'Note D - PPE'!G44 -> -72101.024 | I16: =-'Note D - PPE'!H44 -> -90135.724 | J16: =-'Note D - PPE'!I44 -> -108171.33 | K16: =-'Note D - PPE'!J44 -> -126208.43 | L16: =-'Note D - PPE'!K44 -> -144246.43 | ... U16: =-'Note D - PPE'!T44 -> -1130109.3
B17: Net PP&E | E17: =SUM(E15:E16) -> 3644997.6 | F17: =SUM(F15:F16) -> 3629451.2 | G17: =SUM(G15:G16) -> 3613980.3 | H17: =SUM(H15:H16) -> 3598585 | I17: =SUM(I15:I16) -> 3583265.1 | J17: =SUM(J15:J16) -> 3568020.7 | K17: =SUM(K15:K16) -> 3552899.5 | L17: =SUM(L15:L16) -> 3537853.8 | ... U17: =SUM(U15:U16) -> 2911836.4
B19: Financing Fee | D19: ='Key Assumptions & Drivers'!$D$98*'Key Assumptions & Drivers'!$D$99 -> 62208 | E19: =D19-'Summary P&L'!D29 -> 60652.8 | F19: =E19-'Summary P&L'!E29 -> 60393.6 | G19: =F19-'Summary P&L'!F29 -> 60134.4 | H19: =G19-'Summary P&L'!G29 -> 59875.2 | I19: =H19-'Summary P&L'!H29 -> 59616 | J19: =I19-'Summary P&L'!I29 -> 59356.8 | K19: =J19-'Summary P&L'!J29 -> 59097.6 | L19: =K19-'Summary P&L'!K29 -> 58838.4 | ... P19: =O19-'Summary P&L'!O29 -> 57801.6 | Q19: =P19 -> 57801.6 | R19: =Q19-'Summary P&L'!Q29 -> 54691.2 | S19: =R19-'Summary P&L'!R29 -> 51580.8 | T19: =S19-'Summary P&L'!S29 -> 48470.4 | U19: =T19-'Summary P&L'!T29 -> 45360
B21: Total Assets | D21: =D17+D13+D19 -> 4138000 | E21: =E17+E13+E19 -> 3944134.5 | F21: =F17+F13+F19 -> 3919285.3 | G21: =G17+G13+G19 -> 3918800.8 | H21: =H17+H13+H19 -> 3920180.9 | I21: =I17+I13+I19 -> 3923425.7 | J21: =J17+J13+J19 -> 3928535.1 | K21: =K17+K13+K19 -> 3936834.4 | ... U21: =U17+U13+U19 -> 4684265.1
B24: Current Liabilities
B25: AP
B26: Accrued
B27: Gift Cards
B29: Total Current Liabilities | D29: =SUM(D24:D27) -> 0 | E29: =SUM(E24:E27) -> 0 | F29: =SUM(F24:F27) -> 0 | G29: =SUM(G24:G27) -> 0 | H29: =SUM(H24:H27) -> 0 | I29: =SUM(I24:I27) -> 0 | J29: =SUM(J24:J27) -> 0 | K29: =SUM(K24:K27) -> 0 | ... U29: =SUM(U24:U27) -> 0
B31: Bank Loan - 20 years @ 4.75% | D31: -3110400 | E31: =D31-'Cash Flow'!G22 -> -3074048.1 | F31: =E31-'Cash Flow'!H22 -> -3068042.3 | G31: =F31-'Cash Flow'!I22 -> -3062001.6 | H31: =G31-'Cash Flow'!J22 -> -3055925.6 | I31: =H31-'Cash Flow'!K22 -> -3049814.1 | J31: =I31-'Cash Flow'!L22 -> -3043667.1 | K31: =J31-'Cash Flow'!M22 -> -3037484.1 | L31: =K31-'Cash Flow'!N22 -> -3031265.1 | ... P31: =O31-'Cash Flow'!R22 -> -3006024.1 | Q31: =P31 -> -3006024.1 | R31: =Q31-'Cash Flow'!T22 -> -2926680.2 | S31: =R31-'Cash Flow'!U22 -> -2841600.4 | T31: =S31-'Cash Flow'!V22 -> -2750370.3 | U31: =T31-'Cash Flow'!W22 -> -2652545.1
B33: Total Liabilities | D33: =D31+D29 -> -3110400 | E33: =E31+E29 -> -3074048.1 | F33: =F31+F29 -> -3068042.3 | G33: =G31+G29 -> -3062001.6 | H33: =H31+H29 -> -3055925.6 | I33: =I31+I29 -> -3049814.1 | J33: =J31+J29 -> -3043667.1 | K33: =K31+K29 -> -3037484.1 | ... U33: =U31+U29 -> -2652545.1
B35: Shareholders Equity
B36: Contributed Capital | D36: =-'Key Assumptions & Drivers'!$D$111 -> -1027600 | E36: =D36 -> -1027600 | F36: =E36 -> -1027600 | G36: =F36 -> -1027600 | H36: =G36 -> -1027600 | I36: =H36 -> -1027600 | J36: =I36 -> -1027600 | K36: =J36 -> -1027600 | L36: =K36 -> -1027600 | ... U36: =T36 -> -1027600
B37: Draws - Owner Taxes | C37: ='Key Assumptions & Drivers'!$D$112 -> 0.25 | R37: =R39*-$C$37 -> 75664.58 | S37: =S39*-$C$37 -> 82329.825 | T37: =T39*-$C$37 -> 89282.372 | U37: =U39*-$C$37 -> 96537.777
B38: Draws - Cumulative | R38: =Q37 -> 0 | S38: =SUM(Q37:R37) -> 75664.58 | T38: =SUM(Q37:S37) -> 157994.41 | U38: =SUM(Q37:T37) -> 247276.78
B39: Retained Earnings - Current | E39: =-'Summary P&L'!D35 -> 157513.59 | F39: =-'Summary P&L'!E35 -> 18843.455 | G39: =-'Summary P&L'!F35 -> -5556.2329 | H39: =-'Summary P&L'!G35 -> -7456.1249 | I39: =-'Summary P&L'!H35 -> -9356.2225 | J39: =-'Summary P&L'!I35 -> -11256.527 | K39: =-'Summary P&L'!J35 -> -14482.215 | L39: =-'Summary P&L'!K35 -> -16382.936 | ... U39: =-'Summary P&L'!T35 -> -386151.11
B40: Ret. Earnings Cumulative | E40: =E39 -> 157513.59 | F40: =F39+E40 -> 176357.04 | G40: =G39+F40 -> 170800.81 | H40: =H39+G40 -> 163344.68 | I40: =I39+H40 -> 153988.46 | J40: =J39+I40 -> 142731.94 | K40: =K39+J40 -> 128249.72 | L40: =L39+K40 -> 111866.78 | M40: =M39+L40 -> 93582.917 | ... P40: =P39+O40 -> 27323.599 | Q40: =Q39 -> 27323.599 | R40: =R39+Q40 -> -275334.72 | S40: =S39+R40 -> -604654.02 | T40: =T39+S40 -> -961783.51 | U40: =U39+T40 -> -1347934.6
B42: Total Liabilities & Inv. Equity | D42: =D40+D36+D33+D37+D38 -> -4138000 | E42: =E40+E36+E33+E37+E38 -> -3944134.5 | F42: =F40+F36+F33+F37+F38 -> -3919285.3 | G42: =G40+G36+G33+G37+G38 -> -3918800.8 | H42: =H40+H36+H33+H37+H38 -> -3920180.9 | I42: =I40+I36+I33+I37+I38 -> -3923425.7 | J42: =J40+J36+J33+J37+J38 -> -3928535.1 | K42: =K40+K36+K33+K37+K38 -> -3936834.4 | ... U42: =U40+U36+U33+U37+U38 -> -4684265.1
C44: chk | D44: =D21+D42 -> 0 | E44: =E21+E42 -> 0 | F44: =F21+F42 -> 0 | G44: =G21+G42 -> -2e-08 | H44: =H21+H42 -> -2e-08 | I44: =I21+I42 -> -2e-08 | J44: =J21+J42 -> -2e-08 | K44: =K21+K42 -> -2e-08 | ... U44: =U21+U42 -> -1e-08

Sheet Cash Flow
D2: STATEMENT OF CASH FLOWS
G5: 6 Months
E6: Note | F6: Opening | G6: Construction | H6: 45139 | I6: 45170 | J6: 45200 | K6: 45231 | L6: 45261 | M6: 45292 | N6: 45323 | O6: 45352 | P6: 45383 | Q6: 45413 | R6: 45444 | S6: Year 1 | T6: 45444 | U6: 45809 | V6: 46174 | W6: 46539
F7: (est.) | G7: (est.) | H7: (est.) | I7: (est.) | J7: (est.) | K7: (est.) | L7: (est.) | M7: (est.) | N7: (est.) | O7: (est.) | P7: (est.) | Q7: (est.) | R7: (est.) | S7: (est.) | T7: (est.) | U7: (est.) | V7: (est.) | W7: (est.)
D9: Net Earnings | F9: 0 | G9: ='Summary P&L'!D35 -> -157513.59 | H9: ='Summary P&L'!E35 -> -18843.455 | I9: ='Summary P&L'!F35 -> 5556.2329 | J9: ='Summary P&L'!G35 -> 7456.1249 | K9: ='Summary P&L'!H35 -> 9356.2225 | L9: ='Summary P&L'!I35 -> 11256.527 | M9: ='Summary P&L'!J35 -> 14482.215 | N9: ='Summary P&L'!K35 -> 16382.936 | ... W9: ='Summary P&L'!T35 -> 386151.11
D11: Depreciation and Amortization | F11: 0 | G11: ='Note D - PPE'!D43 -> 18002.381 | H11: ='Note D - PPE'!E43 -> 18031.971 | I11: ='Note D - PPE'!F43 -> 18032.881 | J11: ='Note D - PPE'!G43 -> 18033.791 | K11: ='Note D - PPE'!H43 -> 18034.7 | L11: ='Note D - PPE'!I43 -> 18035.61 | M11: ='Note D - PPE'!J43 -> 18037.094 | N11: ='Note D - PPE'!K43 -> 18038.003 | ... W11: ='Note D - PPE'!T43 -> 229108.92
D13: Changes in Other Assests/Liabilities | F13: =-'Balance Sheet'!D19 -> -62208 | G13: ='Balance Sheet'!D19-'Balance Sheet'!E19 -> 1555.2 | H13: ='Balance Sheet'!E19-'Balance Sheet'!F19 -> 259.2 | I13: ='Balance Sheet'!F19-'Balance Sheet'!G19 -> 259.2 | J13: ='Balance Sheet'!G19-'Balance Sheet'!H19 -> 259.2 | K13: ='Balance Sheet'!H19-'Balance Sheet'!I19 -> 259.2 | L13: ='Balance Sheet'!I19-'Balance Sheet'!J19 -> 259.2 | M13: ='Balance Sheet'!J19-'Balance Sheet'!K19 -> 259.2 | N13: ='Balance Sheet'!K19-'Balance Sheet'!L19 -> 259.2 | ... R13: ='Balance Sheet'!O19-'Balance Sheet'!P19 -> 259.2 | S13: =SUM(G13:R13) -> 4406.4 | T13: ='Balance Sheet'!Q19-'Balance Sheet'!R19 -> 3110.4 | U13: ='Balance Sheet'!R19-'Balance Sheet'!S19 -> 3110.4 | V13: ='Balance Sheet'!S19-'Balance Sheet'!T19 -> 3110.4 | W13: ='Balance Sheet'!T19-'Balance Sheet'!U19 -> 3110.4
D15: Net Cash from Operations | F15: =SUM(F9:F14) -> -62208 | G15: =SUM(G9:G14) -> -137956.01 | H15: =SUM(H9:H14) -> -552.28366 | I15: =SUM(I9:I14) -> 23848.314 | J15: =SUM(J9:J14) -> 25749.116 | K15: =SUM(K9:K14) -> 27650.123 | L15: =SUM(L9:L14) -> 29551.337 | M15: =SUM(M9:M14) -> 32778.508 | ... W15: =SUM(W9:W14) -> 618370.42
D17: Investments
D18: Purchase of PP&E | G18: =-'Note D - PPE'!D28 -> -3663000 | H18: =-'Note D - PPE'!E25 -> -2485.5759 | I18: =-'Note D - PPE'!F25 -> -2561.9953 | J18: =-'Note D - PPE'!G25 -> -2638.4147 | K18: =-'Note D - PPE'!H25 -> -2714.8342 | L18: =-'Note D - PPE'!I25 -> -2791.2536 | M18: =-'Note D - PPE'!J25 -> -2915.8561 | N18: =-'Note D - PPE'!K25 -> -2992.2755 | O18: =-'Note D - PPE'!L25 -> -3068.695 | ... R18: =-'Note D - PPE'!O25 -> -3297.9532 | S18: =SUM(G18:R18) -> -3694833.5 | T18: =-'Note D - PPE'!Q25 -> -82164.467 | U18: =-'Note D - PPE'!R25 -> -85128.283 | V18: =-'Note D - PPE'!S25 -> -88257.019 | W18: =-'Note D - PPE'!T25 -> -91562.423
D20: Financing transactions
D21: Gross Loan Proceeds | F21: ='Key Assumptions & Drivers'!D98 -> 3110400
D22: Payback of Bank Loans | G22: =-SUM('Note E - Loan Amortization'!H20:H25) -> -36351.923 | H22: =-'Note E - Loan Amortization'!H21 -> -6005.7283 | I22: =-'Note E - Loan Amortization'!H22 -> -6040.7617 | J22: =-'Note E - Loan Amortization'!H23 -> -6075.9995 | K22: =-'Note E - Loan Amortization'!H24 -> -6111.4429 | L22: =-'Note E - Loan Amortization'!H25 -> -6147.0929 | M22: =-'Note E - Loan Amortization'!H26 -> -6182.951 | N22: =-'Note E - Loan Amortization'!H27 -> -6219.0182 | O22: =-'Note E - Loan Amortization'!H28 -> -6255.2958 | P22: =-'Note E - Loan Amortization'!H29 -> -6291.785 | Q22: =-'Note E - Loan Amortization'!H30 -> -6328.4871 | R22: =-'Note E - Loan Amortization'!H31 -> -6365.4033 | S22: =SUM(G22:R22) -> -104375.89 | T22: =-'Note E - Loan Amortization'!L43 -> -79343.959 | U22: =-'Note E - Loan Amortization'!L55 -> -85079.74 | V22: =-'Note E - Loan Amortization'!L67 -> -91230.161 | W22: =-'Note E - Loan Amortization'!L79 -> -97825.197
D23: Net Financing Transactions | F23: =SUM(F21:F22) -> 3110400 | G23: =G22+G21 -> -36351.923 | H23: =H22+H21 -> -6005.7283 | I23: =I22+I21 -> -6040.7617 | J23: =J22+J21 -> -6075.9995 | K23: =K22+K21 -> -6111.4429 | L23: =L22+L21 -> -6147.0929 | M23: =M22+M21 -> -6182.951 | N23: =N22+N21 -> -6219.0182 | ... W23: =W22+W21 -> -97825.197
D25: Equity Transactions | E25: Cont/Draws | F25: =-'Balance Sheet'!D36 -> 1027600 | R25: =-'Balance Sheet'!P37 -> 0 | S25: =-'Balance Sheet'!Q37 -> 0 | T25: =-'Balance Sheet'!R37 -> -75664.58 | U25: =-'Balance Sheet'!S37 -> -82329.825 | V25: =-'Balance Sheet'!T37 -> -89282.372 | W25: =-'Balance Sheet'!U37 -> -96537.777
F26: Working Cap | S26: Draw - Taxes | T26: Draw - Taxes | U26: Draw - Taxes | V26: Draw - Taxes | W26: Draw - Taxes
D27: Net Change in Cash | F27: =F25+F23+F15 -> 4075792 | G27: =G15+G18+G23+G25 -> -3837307.9 | H27: =H15+H18+H23+H25 -> -9043.5879 | I27: =I15+I18+I23+I25 -> 15245.557 | J27: =J15+J18+J23+J25 -> 17034.701 | K27: =K15+K18+K23+K25 -> 18823.846 | L27: =L15+L18+L23+L25 -> 20612.99 | M27: =M15+M18+M23+M25 -> 23679.701 | N27: =N15+N18+N23+N25 -> 25468.846 | ... W27: =W15+W18+W23+W25 -> 332445.03
D29: Cash End of Period | F29: =F27+E9 -> 4075792 | G29: =G27+F29 -> 238484.07 | H29: =H27+G29 -> 229440.48 | I29: =I27+H29 -> 244686.04 | J29: =J27+I29 -> 261720.74 | K29: =K27+J29 -> 280544.59 | L29: =L27+K29 -> 301157.58 | M29: =M27+L29 -> 324837.28 | N29: =N27+M29 -> 350306.12 | ... R29: =R27+Q29 -> 470072.95 | S29: =S27+F29 -> 470072.95 | T29: =T27+S29 -> 766435.02 | U29: =U27+T29 -> 1074516.6 | V29: =V27+U29 -> 1394623.7 | W29: =W27+V29 -> 1727068.7

Sheet Notes to FS ---->
Q21: - Notes & Support to Financial Statements
Q24: August 2017

Sheet Notes A&B - Revenue & COGS
B2: NOTES A & B TO FINANCIAL STATEMENTS
B5: Revenue - Note A | E5: 6 Months
C6: Note | E6: Construction | F6: 43313 | G6: 43344 | H6: 43374 | I6: 43405 | J6: 43435 | K6: 43466 | L6: 43497 | M6: 43525 | N6: 43556 | O6: 43586 | P6: 43617 | Q6: Year 1 | R6: 43983 | S6: 44348 | T6: 44713 | U6: 45078
E7: (est.) | F7: (est.) | G7: (est.) | H7: (est.) | I7: (est.) | J7: (est.) | K7: (est.) | L7: (est.) | M7: (est.) | N7: (est.) | O7: (est.) | P7: (est.) | Q7: (est.) | R7: (est.) | S7: (est.) | T7: (est.) | U7: (est.)
B9: Number of Cars Captured | E9: ='Key Assumptions & Drivers'!D36 -> 0 | F9: ='Key Assumptions & Drivers'!E36 -> 6322.8471 | G9: ='Key Assumptions & Drivers'!F36 -> 6322.8471 | H9: ='Key Assumptions & Drivers'!G36 -> 6322.8471 | I9: ='Key Assumptions & Drivers'!H36 -> 6322.8471 | J9: ='Key Assumptions & Drivers'!I36 -> 6322.8471 | K9: ='Key Assumptions & Drivers'!J36 -> 6449.304 | L9: ='Key Assumptions & Drivers'!K36 -> 6449.304 | ... P9: ='Key Assumptions & Drivers'!O36 -> 6449.304 | Q9: =SUM(E9:P9) -> 70310.059 | R9: ='Key Assumptions & Drivers'!P36 -> 78939.481 | S9: ='Key Assumptions & Drivers'!Q36 -> 80518.271 | T9: ='Key Assumptions & Drivers'!R36 -> 82128.636 | U9: ='Key Assumptions & Drivers'!S36 -> 83771.209
B10: Avg Price per Car | C10: ='Key Assumptions & Drivers'!$D$19 -> 12.96 | E10: 0 | F10: =$C$10 -> 12.96 | G10: =$C$10 -> 12.96 | H10: =$C$10 -> 12.96 | I10: =$C$10 -> 12.96 | J10: =$C$10 -> 12.96 | K10: =$C$10 -> 12.96 | L10: =$C$10 -> 12.96 | M10: =$C$10 -> 12.96 | ... P10: =$C$10 -> 12.96 | Q10: =P10 -> 12.96 | R10: =$C$10 -> 12.96 | S10: =$C$10 -> 12.96 | T10: =$C$10 -> 12.96 | U10: =$C$10 -> 12.96
B12: Total Subscribers | F12: ='Key Assumptions & Drivers'!E28 -> 100 | G12: ='Key Assumptions & Drivers'!F28 -> 200 | H12: ='Key Assumptions & Drivers'!G28 -> 300 | I12: ='Key Assumptions & Drivers'!H28 -> 400 | J12: ='Key Assumptions & Drivers'!I28 -> 500 | K12: ='Key Assumptions & Drivers'!J28 -> 600 | L12: ='Key Assumptions & Drivers'!K28 -> 700 | M12: ='Key Assumptions & Drivers'!L28 -> 800 | ... P12: ='Key Assumptions & Drivers'!O28 -> 1100 | Q12: =P12 -> 1100 | R12: ='Key Assumptions & Drivers'!P28 -> 1200 | S12: ='Key Assumptions & Drivers'!Q28 -> 1296 | T12: ='Key Assumptions & Drivers'!R28 -> 1399.68 | U12: ='Key Assumptions & Drivers'!S28 -> 1511.6544
B13: Average Price / Subscriber | C13: ='Key Assumptions & Drivers'!$D$22 -> 25.993 | F13: =$C$13 -> 25.993 | G13: =$C$13 -> 25.993 | H13: =$C$13 -> 25.993 | I13: =$C$13 -> 25.993 | J13: =$C$13 -> 25.993 | K13: =$C$13 -> 25.993 | L13: =$C$13 -> 25.993 | M13: =$C$13 -> 25.993 | ... U13: =$C$13 -> 25.993
B15: Revenue from Car Wash | E15: =(E9*E10)+(E12*E13) -> 0 | F15: =(F9*F10)+(F12*F13) -> 84543.398 | G15: =(G9*G10)+(G12*G13) -> 87142.698 | H15: =(H9*H10)+(H12*H13) -> 89741.998 | I15: =(I9*I10)+(I12*I13) -> 92341.298 | J15: =(J9*J10)+(J12*J13) -> 94940.598 | K15: =(K9*K10)+(K12*K13) -> 99178.78 | L15: =(L9*L10)+(L12*L13) -> 101778.08 | ... P15: =(P9*P10)+(P12*P13) -> 112175.28 | Q15: =SUM(F15:P15) -> 1082772.2 | R15: =(R9*R10)+(R12*R13*12) -> 1397354.9 | S15: =(S9*S10)+(S12*S13*12) -> 1447759.9 | T15: =(T9*T10)+(T12*T13*12) -> 1500969.7 | U15: =(U9*U10)+(U12*U13*12) -> 1557184.1
B17: Merchandise Revenue | E17: 0 | F17: 0 | G17: 0 | H17: 0 | I17: 0 | J17: 0 | K17: 0 | L17: 0 | M17: 0 | N17: 0 | O17: 0 | P17: 0 | Q17: 0 | R17: 0 | S17: 0 | T17: 0 | U17: 0
B18: Total Revenue | E18: =E15+E17 -> 0 | F18: =F15+F17 -> 84543.398 | G18: =G15+G17 -> 87142.698 | H18: =H15+H17 -> 89741.998 | I18: =I15+I17 -> 92341.298 | J18: =J15+J17 -> 94940.598 | K18: =K15+K17 -> 99178.78 | L18: =L15+L17 -> 101778.08 | ... U18: =U15+U17 -> 1557184.1
B20: Less:
B21: CC Processing (% of Rev.) | C21: ='Key Assumptions & Drivers'!$D$11 -> 0.02 | E21: =-E18*$C$21 -> 0 | F21: =-F18*$C$21 -> -1690.868 | G21: =-G18*$C$21 -> -1742.854 | H21: =-H18*$C$21 -> -1794.84 | I21: =-I18*$C$21 -> -1846.826 | J21: =-J18*$C$21 -> -1898.812 | K21: =-K18*$C$21 -> -1983.5756 | L21: =-L18*$C$21 -> -2035.5616 | ... P21: =-P18*$C$21 -> -2243.5056 | Q21: =SUM(E21:P21) -> -21655.443 | R21: =-R18*$C$21 -> -27947.097 | S21: =-S18*$C$21 -> -28955.198 | T21: =-T18*$C$21 -> -30019.394 | U21: =-U18*$C$21 -> -31143.681
B22: Merchandise Cost | E22: 0 | F22: 0 | G22: 0 | H22: 0 | I22: 0 | J22: 0 | K22: 0 | L22: 0 | M22: 0 | N22: 0 | O22: 0 | P22: 0 | Q22: 0 | R22: 0 | S22: 0 | T22: 0 | U22: 0
B24: Net Revenue | E24: =E18+E21+E22 -> 0 | F24: =F18+F21+F22 -> 82852.53 | G24: =G18+G21+G22 -> 85399.844 | H24: =H18+H21+H22 -> 87947.158 | I24: =I18+I21+I22 -> 90494.472 | J24: =J18+J21+J22 -> 93041.786 | K24: =K18+K21+K22 -> 97195.204 | L24: =L18+L21+L22 -> 99742.518 | ... U24: =U18+U21+U22 -> 1526040.4
B28: COGS - Note B
C29: Note | E29: Construction | F29: 43313 | G29: 43344 | H29: 43374 | I29: 43405 | J29: 43435 | K29: 43466 | L29: 43497 | M29: 43525 | N29: 43556 | O29: 43586 | P29: 43617 | Q29: Year 1 | R29: 43983 | S29: 44348 | T29: 44713 | U29: 45078
E30: (est.) | F30: (est.) | G30: (est.) | H30: (est.) | I30: (est.) | J30: (est.) | K30: (est.) | L30: (est.) | M30: (est.) | N30: (est.) | O30: (est.) | P30: (est.) | Q30: (est.) | R30: (est.) | S30: (est.) | T30: (est.) | U30: (est.)
B31: Variable Cost
B33: Utilities | C33: Note F | E33: ='Note F - Other analysis'!E23 -> 0 | F33: ='Note F - Other analysis'!F23 -> 3904.2712 | G33: ='Note F - Other analysis'!G23 -> 4052.7712 | H33: ='Note F - Other analysis'!H23 -> 4201.2712 | I33: ='Note F - Other analysis'!I23 -> 4349.7712 | J33: ='Note F - Other analysis'!J23 -> 4498.2712 | K33: ='Note F - Other analysis'!K23 -> 4721.8866 | L33: ='Note F - Other analysis'!L23 -> 4870.3866 | ... U33: ='Note F - Other analysis'!U23 -> 76697.779
B34: Supplies | C34: Note F | E34: ='Note F - Other analysis'!E18 -> 0 | F34: ='Note F - Other analysis'!F18 -> 262.91388 | G34: ='Note F - Other analysis'!G18 -> 272.91388 | H34: ='Note F - Other analysis'!H18 -> 282.91388 | I34: ='Note F - Other analysis'!I18 -> 292.91388 | J34: ='Note F - Other analysis'!J18 -> 302.91388 | K34: ='Note F - Other analysis'!K18 -> 317.97216 | L34: ='Note F - Other analysis'!L18 -> 327.97216 | ... U34: ='Note F - Other analysis'!U18 -> 5164.8336
B35: Wtd Avg Chem Cost | C35: Note F | E35: ='Note F - Other analysis'!E19 -> 0 | F35: ='Note F - Other analysis'!F19 -> 7798.0125 | G35: ='Note F - Other analysis'!G19 -> 8217.2625 | H35: ='Note F - Other analysis'!H19 -> 8636.5125 | I35: ='Note F - Other analysis'!I19 -> 9055.7625 | J35: ='Note F - Other analysis'!J19 -> 9475.0125 | K35: ='Note F - Other analysis'!K19 -> 10041.838 | L35: ='Note F - Other analysis'!L19 -> 10461.088 | ... U35: ='Note F - Other analysis'!U19 -> 173812.33
B36: Direct Labor & Burden | C36: Note F | E36: ='Note F - Other analysis'!E32 -> 0 | F36: ='Note F - Other analysis'!F32 -> 6071.8667 | G36: ='Note F - Other analysis'!G32 -> 6071.8667 | H36: ='Note F - Other analysis'!H32 -> 6071.8667 | I36: ='Note F - Other analysis'!I32 -> 6071.8667 | J36: ='Note F - Other analysis'!J32 -> 6071.8667 | K36: ='Note F - Other analysis'!K32 -> 6071.8667 | L36: ='Note F - Other analysis'!L32 -> 6071.8667 | ... U36: ='Note F - Other analysis'!U32 -> 91987.101
B37: Auto Claims | C37: Note F | E37: ='Note F - Other analysis'!E17 -> 0 | F37: ='Note F - Other analysis'!F17 -> 394.37082 | G37: ='Note F - Other analysis'!G17 -> 409.37082 | H37: ='Note F - Other analysis'!H17 -> 424.37082 | I37: ='Note F - Other analysis'!I17 -> 439.37082 | J37: ='Note F - Other analysis'!J17 -> 454.37082 | K37: ='Note F - Other analysis'!K17 -> 476.95824 | L37: ='Note F - Other analysis'!L17 -> 491.95824 | ... U37: ='Note F - Other analysis'!U17 -> 7747.2504
B38: R&M | C38: Note F | E38: ='Note F - Other analysis'!E25 -> 0 | F38: ='Note F - Other analysis'!F25 -> 953.06282 | G38: ='Note F - Other analysis'!G25 -> 989.31282 | H38: ='Note F - Other analysis'!H25 -> 1025.5628 | I38: ='Note F - Other analysis'!I25 -> 1061.8128 | J38: ='Note F - Other analysis'!J25 -> 1098.0628 | K38: ='Note F - Other analysis'!K25 -> 1152.6491 | L38: ='Note F - Other analysis'!L25 -> 1188.8991 | ... U38: ='Note F - Other analysis'!U25 -> 18722.522
B39: Total Variable Cost | E39: =SUM(E32:E38) -> 0 | F39: =SUM(F32:F38) -> 19384.498 | G39: =SUM(G32:G38) -> 20013.498 | H39: =SUM(H32:H38) -> 20642.498 | I39: =SUM(I32:I38) -> 21271.498 | J39: =SUM(J32:J38) -> 21900.498 | K39: =SUM(K32:K38) -> 22783.17 | L39: =SUM(L32:L38) -> 23412.17 | ... T39: =SUM(T32:T38) -> 357178.17 | U39: =SUM(U31:U38) -> 374131.82
B40: Total Variable Margin | E40: =E24-E39 -> 0 | F40: =F24-F39 -> 63468.032 | G40: =G24-G39 -> 65386.346 | H40: =H24-H39 -> 67304.66 | I40: =I24-I39 -> 69222.974 | J40: =J24-J39 -> 71141.288 | K40: =K24-K39 -> 74412.034 | L40: =L24-L39 -> 76330.348 | ... U40: =U24-U39 -> 1151908.6
B41: Variable Margin % | E41: =_xlfn.IFERROR(IF((E40/E24)<0,0,(E40/E24)),0) -> 0 | F41: =_xlfn.IFERROR(IF((F40/F24)<0,0,(F40/F24)),0) -> 0.76603614 | G41: =_xlfn.IFERROR(IF((G40/G24)<0,0,(G40/G24)),0) -> 0.76564948 | H41: =_xlfn.IFERROR(IF((H40/H24)<0,0,(H40/H24)),0) -> 0.76528522 | I41: =_xlfn.IFERROR(IF((I40/I24)<0,0,(I40/I24)),0) -> 0.76494147 | J41: =_xlfn.IFERROR(IF((J40/J24)<0,0,(J40/J24)),0) -> 0.76461654 | K41: =_xlfn.IFERROR(IF((K40/K24)<0,0,(K40/K24)),0) -> 0.76559368 | L41: =_xlfn.IFERROR(IF((L40/L24)<0,0,(L40/L24)),0) -> 0.76527392 | ... U41: =_xlfn.IFERROR(IF((U40/U24)<0,0,(U40/U24)),0) -> 0.75483491
B43: Other Cost of Goods sold
B44: Depreciation of PP&E | C44: Note D | E44: ='Note D - PPE'!D43 -> 18002.381 | F44: ='Note D - PPE'!E43 -> 18031.971 | G44: ='Note D - PPE'!F43 -> 18032.881 | H44: ='Note D - PPE'!G43 -> 18033.791 | I44: ='Note D - PPE'!H43 -> 18034.7 | J44: ='Note D - PPE'!I43 -> 18035.61 | K44: ='Note D - PPE'!J43 -> 18037.094 | L44: ='Note D - PPE'!K43 -> 18038.003 | ... U44: ='Note D - PPE'!T43 -> 229108.92
B45: Property Taxes | C45: Note D | E45: =$Q$45/12 -> 4618.5419 | F45: =$Q$45/12 -> 4618.5419 | G45: =$Q$45/12 -> 4618.5419 | H45: =$Q$45/12 -> 4618.5419 | I45: =$Q$45/12 -> 4618.5419 | J45: =$Q$45/12 -> 4618.5419 | K45: =$Q$45/12 -> 4618.5419 | L45: =$Q$45/12 -> 4618.5419 | ... P45: =$Q$45/12 -> 4618.5419 | Q45: ='Note D - PPE'!P30 -> 55422.503 | R45: ='Note D - PPE'!Q30 -> 56917.47 | S45: ='Note D - PPE'!R30 -> 58462.144 | T45: ='Note D - PPE'!S30 -> 60059.104 | U45: ='Note D - PPE'!T30 -> 61711.107
B46: Total Other COGS | E46: =SUM(E44:E45) -> 22620.923 | F46: =SUM(F44:F45) -> 22650.513 | G46: =SUM(G44:G45) -> 22651.423 | H46: =SUM(H44:H45) -> 22652.333 | I46: =SUM(I44:I45) -> 22653.242 | J46: =SUM(J44:J45) -> 22654.152 | K46: =SUM(K44:K45) -> 22655.635 | L46: =SUM(L44:L45) -> 22656.545 | ... U46: =SUM(U44:U45) -> 290820.03
B47: Total Gross Margin | E47: =E40-E46 -> -22620.923 | F47: =F40-F46 -> 40817.519 | G47: =G40-G46 -> 42734.923 | H47: =H40-H46 -> 44652.328 | I47: =I40-I46 -> 46569.732 | J47: =J40-J46 -> 48487.136 | K47: =K40-K46 -> 51756.398 | L47: =L40-L46 -> 53673.803 | ... U47: =U40-U46 -> 861088.53
B48: Gross Margin % | E48: =_xlfn.IFERROR(E47/E24,0) -> 0 | F48: =_xlfn.IFERROR(F47/F24,0) -> 0.49265266 | G48: =_xlfn.IFERROR(G47/G24,0) -> 0.50040985 | H48: =_xlfn.IFERROR(H47/H24,0) -> 0.50771769 | I48: =_xlfn.IFERROR(I47/I24,0) -> 0.51461411 | J48: =_xlfn.IFERROR(J47/J24,0) -> 0.5211329 | K48: =_xlfn.IFERROR(K47/K24,0) -> 0.53249951 | L48: =_xlfn.IFERROR(L47/L24,0) -> 0.5381236 | ... U48: =_xlfn.IFERROR(U47/U24,0) -> 0.56426327

Sheet Note C - SG&A
B2: NOTE C TO FINANCIAL STATEMENTS
B5: SGA Note C | D5: 6 Months
C6: Note | D6: Construction | E6: 43313 | F6: 43344 | G6: 43374 | H6: 43405 | I6: 43435 | J6: 43466 | K6: 43497 | L6: 43525 | M6: 43556 | N6: 43586 | O6: 43617 | P6: Year 1 | Q6: 43983 | R6: 44348 | S6: 44713 | T6: 45078
D7: (est.) | E7: (est.) | F7: (est.) | G7: (est.) | H7: (est.) | I7: (est.) | J7: (est.) | K7: (est.) | L7: (est.) | M7: (est.) | N7: (est.) | O7: (est.) | P7: (est.) | Q7: (est.) | R7: (est.) | S7: (est.) | T7: (est.)
B8: Employee Cost
B9: Salaries | C9: See below | D9: =(D31*'Key Assumptions & Drivers'!$D$72)+(D34*'Key Assumptions & Drivers'!$D$73)+(D37*'Key Assumptions & Drivers'!$D$74)+(D40*'Key Assumptions & Drivers'!$D$75) -> 0 | E9: =(E31*'Key Assumptions & Drivers'!$D$72)+(E34*'Key Assumptions & Drivers'!$D$73)+(E37*'Key Assumptions & Drivers'!$D$74)+(E40*'Key Assumptions & Drivers'!$D$75) -> 8146.6667 | F9: =(F31*'Key Assumptions & Drivers'!$D$72)+(F34*'Key Assumptions & Drivers'!$D$73)+(F37*'Key Assumptions & Drivers'!$D$74)+(F40*'Key Assumptions & Drivers'!$D$75) -> 8146.6667 | G9: =(G31*'Key Assumptions & Drivers'!$D$72)+(G34*'Key Assumptions & Drivers'!$D$73)+(G37*'Key Assumptions & Drivers'!$D$74)+(G40*'Key Assumptions & Drivers'!$D$75) -> 8146.6667 | H9: =(H31*'Key Assumptions & Drivers'!$D$72)+(H34*'Key Assumptions & Drivers'!$D$73)+(H37*'Key Assumptions & Drivers'!$D$74)+(H40*'Key Assumptions & Drivers'!$D$75) -> 8146.6667 | I9: =(I31*'Key Assumptions & Drivers'!$D$72)+(I34*'Key Assumptions & Drivers'!$D$73)+(I37*'Key Assumptions & Drivers'!$D$74)+(I40*'Key Assumptions & Drivers'!$D$75) -> 8146.6667 | J9: =(J31*'Key Assumptions & Drivers'!$D$72)+(J34*'Key Assumptions & Drivers'!$D$73)+(J37*'Key Assumptions & Drivers'!$D$74)+(J40*'Key Assumptions & Drivers'!$D$75) -> 8146.6667 | K9: =(K31*'Key Assumptions & Drivers'!$D$72)+(K34*'Key Assumptions & Drivers'!$D$73)+(K37*'Key Assumptions & Drivers'!$D$74)+(K40*'Key Assumptions & Drivers'!$D$75) -> 8146.6667 | ... O9: =(O31*'Key Assumptions & Drivers'!$D$72)+(O34*'Key Assumptions & Drivers'!$D$73)+(O37*'Key Assumptions & Drivers'!$D$74)+(O40*'Key Assumptions & Drivers'!$D$75) -> 8146.6667 | P9: =SUM(D9:O9) -> 89613.333 | Q9: =(Q31*'Key Assumptions & Drivers'!$D$72)+(Q34*'Key Assumptions & Drivers'!$D$73)+(Q37*'Key Assumptions & Drivers'!$D$74)+(Q40*'Key Assumptions & Drivers'!$D$75) -> 106288 | R9: =(R31*'Key Assumptions & Drivers'!$D$72)+(R34*'Key Assumptions & Drivers'!$D$73)+(R37*'Key Assumptions & Drivers'!$D$74)+(R40*'Key Assumptions & Drivers'!$D$75) -> 115593.92 | S9: =(S31*'Key Assumptions & Drivers'!$D$72)+(S34*'Key Assumptions & Drivers'!$D$73)+(S37*'Key Assumptions & Drivers'!$D$74)+(S40*'Key Assumptions & Drivers'!$D$75) -> 125751.06 | T9: =(T31*'Key Assumptions & Drivers'!$D$72)+(T34*'Key Assumptions & Drivers'!$D$73)+(T37*'Key Assumptions & Drivers'!$D$74)+(T40*'Key Assumptions & Drivers'!$D$75) -> 136839.78
B10: Burden - Taxes | C10: ='Key Assumptions & Drivers'!$E$76 -> 0.097 | D10: =D9*$C10 -> 0 | E10: =E9*$C10 -> 790.22667 | F10: =F9*$C10 -> 790.22667 | G10: =G9*$C10 -> 790.22667 | H10: =H9*$C10 -> 790.22667 | I10: =I9*$C10 -> 790.22667 | J10: =J9*$C10 -> 790.22667 | K10: =K9*$C10 -> 790.22667 | ... O10: =O9*$C10 -> 790.22667 | P10: =SUM(D10:O10) -> 8692.4933 | Q10: =Q9*$C10 -> 10309.936 | R10: =R9*$C10 -> 11212.61 | S10: =S9*$C10 -> 12197.853 | T10: =T9*$C10 -> 13273.458
B11: Burden - Benefits Load | C11: ='Key Assumptions & Drivers'!$E$77 -> 0.033 | D11: =D9*$C11 -> 0 | E11: =E9*$C11 -> 268.84 | F11: =F9*$C11 -> 268.84 | G11: =G9*$C11 -> 268.84 | H11: =H9*$C11 -> 268.84 | I11: =I9*$C11 -> 268.84 | J11: =J9*$C11 -> 268.84 | K11: =K9*$C11 -> 268.84 | ... O11: =O9*$C11 -> 268.84 | P11: =SUM(D11:O11) -> 2957.24 | Q11: =Q9*$C11 -> 3507.504 | R11: =R9*$C11 -> 3814.5994 | S11: =S9*$C11 -> 4149.785 | T11: =T9*$C11 -> 4515.7126
B13: Total Payroll Cost | D13: =SUM(D9:D12) -> 0 | E13: =SUM(E9:E12) -> 9205.7333 | F13: =SUM(F9:F12) -> 9205.7333 | G13: =SUM(G9:G12) -> 9205.7333 | H13: =SUM(H9:H12) -> 9205.7333 | I13: =SUM(I9:I12) -> 9205.7333 | J13: =SUM(J9:J12) -> 9205.7333 | K13: =SUM(K9:K12) -> 9205.7333 | ... T13: =SUM(T9:T12) -> 154628.95
B15: Total Payroll to SG&A | D15: =D13 -> 0 | E15: =E13 -> 9205.7333 | F15: =F13 -> 9205.7333 | G15: =G13 -> 9205.7333 | H15: =H13 -> 9205.7333 | I15: =I13 -> 9205.7333 | J15: =J13 -> 9205.7333 | K15: =K13 -> 9205.7333 | ... T15: =T13 -> 154628.95
C16: Chg @ Note A
B17: Other SGA
B18: Marketing | D18: ='Key Assumptions & Drivers'!$D$63/2 -> 25000 | E18: ='Key Assumptions & Drivers'!$D$63/2 -> 25000 | F18: ='Key Assumptions & Drivers'!$D$64 -> 2500 | G18: ='Key Assumptions & Drivers'!$D$64 -> 2500 | H18: ='Key Assumptions & Drivers'!$D$64 -> 2500 | I18: ='Key Assumptions & Drivers'!$D$64 -> 2500 | J18: ='Key Assumptions & Drivers'!$D$64 -> 2500 | K18: ='Key Assumptions & Drivers'!$D$64 -> 2500 | L18: ='Key Assumptions & Drivers'!$D$64 -> 2500 | M18: ='Key Assumptions & Drivers'!$D$64 -> 2500 | ... O18: ='Key Assumptions & Drivers'!$D$64 -> 2500 | P18: =SUM(D18:O18) -> 75000 | Q18: ='Key Assumptions & Drivers'!$D$64*12 -> 30000 | R18: ='Key Assumptions & Drivers'!$D$64*12 -> 30000 | S18: ='Key Assumptions & Drivers'!$D$64*12 -> 30000 | T18: ='Key Assumptions & Drivers'!$D$64*12 -> 30000
B19: Bank Charges | D19: 0 | E19: ='Key Assumptions & Drivers'!$D$65 -> 200 | F19: ='Key Assumptions & Drivers'!$D$65 -> 200 | G19: ='Key Assumptions & Drivers'!$D$65 -> 200 | H19: ='Key Assumptions & Drivers'!$D$65 -> 200 | I19: ='Key Assumptions & Drivers'!$D$65 -> 200 | J19: ='Key Assumptions & Drivers'!$D$65 -> 200 | K19: ='Key Assumptions & Drivers'!$D$65 -> 200 | L19: ='Key Assumptions & Drivers'!$D$65 -> 200 | ... O19: ='Key Assumptions & Drivers'!$D$65 -> 200 | P19: =SUM(D19:O19) -> 2200 | Q19: ='Key Assumptions & Drivers'!$D$65*12 -> 2400 | R19: ='Key Assumptions & Drivers'!$D$65*12 -> 2400 | S19: ='Key Assumptions & Drivers'!$D$65*12 -> 2400 | T19: ='Key Assumptions & Drivers'!$D$65*12 -> 2400
B20: Insurance-Gen Liab. | D20: 0 | E20: ='Key Assumptions & Drivers'!$D$66/12 -> 2500 | F20: ='Key Assumptions & Drivers'!$D$66/12 -> 2500 | G20: ='Key Assumptions & Drivers'!$D$66/12 -> 2500 | H20: ='Key Assumptions & Drivers'!$D$66/12 -> 2500 | I20: ='Key Assumptions & Drivers'!$D$66/12 -> 2500 | J20: ='Key Assumptions & Drivers'!$D$66/12 -> 2500 | K20: ='Key Assumptions & Drivers'!$D$66/12 -> 2500 | L20: ='Key Assumptions & Drivers'!$D$66/12 -> 2500 | ... O20: ='Key Assumptions & Drivers'!$D$66/12 -> 2500 | P20: =SUM(D20:O20) -> 27500 | Q20: ='Key Assumptions & Drivers'!$D$66 -> 30000 | R20: ='Key Assumptions & Drivers'!$D$66 -> 30000 | S20: ='Key Assumptions & Drivers'!$D$66 -> 30000 | T20: ='Key Assumptions & Drivers'!$D$66 -> 30000
B21: Office/Misc | D21: 0 | E21: ='Key Assumptions & Drivers'!$D$67 -> 1500 | F21: ='Key Assumptions & Drivers'!$D$67 -> 1500 | G21: ='Key Assumptions & Drivers'!$D$67 -> 1500 | H21: ='Key Assumptions & Drivers'!$D$67 -> 1500 | I21: ='Key Assumptions & Drivers'!$D$67 -> 1500 | J21: ='Key Assumptions & Drivers'!$D$67 -> 1500 | K21: ='Key Assumptions & Drivers'!$D$67 -> 1500 | L21: ='Key Assumptions & Drivers'!$D$67 -> 1500 | ... O21: ='Key Assumptions & Drivers'!$D$67 -> 1500 | P21: =SUM(D21:O21) -> 16500 | Q21: ='Key Assumptions & Drivers'!$D$67*12 -> 18000 | R21: ='Key Assumptions & Drivers'!$D$67*12 -> 18000 | S21: ='Key Assumptions & Drivers'!$D$67*12 -> 18000 | T21: ='Key Assumptions & Drivers'!$D$67*12 -> 18000
B22: Computer/Internet | D22: 0 | E22: ='Key Assumptions & Drivers'!$D$68 -> 1500 | F22: ='Key Assumptions & Drivers'!$D$68 -> 1500 | G22: ='Key Assumptions & Drivers'!$D$68 -> 1500 | H22: ='Key Assumptions & Drivers'!$D$68 -> 1500 | I22: ='Key Assumptions & Drivers'!$D$68 -> 1500 | J22: ='Key Assumptions & Drivers'!$D$68 -> 1500 | K22: ='Key Assumptions & Drivers'!$D$68 -> 1500 | L22: ='Key Assumptions & Drivers'!$D$68 -> 1500 | ... O22: ='Key Assumptions & Drivers'!$D$68 -> 1500 | P22: =SUM(D22:O22) -> 16500 | Q22: ='Key Assumptions & Drivers'!$D$68*12 -> 18000 | R22: ='Key Assumptions & Drivers'!$D$68*12 -> 18000 | S22: ='Key Assumptions & Drivers'!$D$68*12 -> 18000 | T22: ='Key Assumptions & Drivers'!$D$68*12 -> 18000
B23: Utilities | C23: Note F | D23: ='Note F - Other analysis'!E24 -> 0 | E23: ='Note F - Other analysis'!F24 -> 433.80791 | F23: ='Note F - Other analysis'!G24 -> 450.30791 | G23: ='Note F - Other analysis'!H24 -> 466.80791 | H23: ='Note F - Other analysis'!I24 -> 483.30791 | I23: ='Note F - Other analysis'!J24 -> 499.80791 | J23: ='Note F - Other analysis'!K24 -> 524.65406 | K23: ='Note F - Other analysis'!L24 -> 541.15406 | ... T23: ='Note F - Other analysis'!U24 -> 8521.9755
B24: R&M | C24: Note F | D24: ='Note F - Other analysis'!E26 -> 0 | E24: ='Note F - Other analysis'!F26 -> 953.06282 | F24: ='Note F - Other analysis'!G26 -> 989.31282 | G24: ='Note F - Other analysis'!H26 -> 1025.5628 | H24: ='Note F - Other analysis'!I26 -> 1061.8128 | I24: ='Note F - Other analysis'!J26 -> 1098.0628 | J24: ='Note F - Other analysis'!K26 -> 1152.6491 | K24: ='Note F - Other analysis'!L26 -> 1188.8991 | ... T24: ='Note F - Other analysis'!U26 -> 18722.522
B25: Total Other SG&A | D25: =SUM(D18:D24) -> 25000 | E25: =SUM(E18:E24) -> 32086.871 | F25: =SUM(F18:F24) -> 9639.6207 | G25: =SUM(G18:G24) -> 9692.3707 | H25: =SUM(H18:H24) -> 9745.1207 | I25: =SUM(I18:I24) -> 9797.8707 | J25: =SUM(J18:J24) -> 9877.3031 | K25: =SUM(K18:K24) -> 9930.0531 | ... T25: =SUM(T18:T24) -> 125644.5
B27: Total SG&A | D27: =D15+D25 -> 25000 | E27: =E15+E25 -> 41292.604 | F27: =F15+F25 -> 18845.354 | G27: =G15+G25 -> 18898.104 | H27: =H15+H25 -> 18950.854 | I27: =I15+I25 -> 19003.604 | J27: =J15+J25 -> 19083.036 | K27: =K15+K25 -> 19135.786 | ... T27: =T15+T25 -> 280273.45
B28: SGA % of sales | D28: =_xlfn.IFERROR(IF((D27/'Notes A&B - Revenue & COGS'!E24)<0,0,(D27/'Notes A&B - Revenue & COGS'!E24)),0) -> 0 | E28: =_xlfn.IFERROR(IF((E27/'Notes A&B - Revenue & COGS'!F24)<0,0,(E27/'Notes A&B - Revenue & COGS'!F24)),0) -> 0.49838676 | F28: =_xlfn.IFERROR(IF((F27/'Notes A&B - Revenue & COGS'!G24)<0,0,(F27/'Notes A&B - Revenue & COGS'!G24)),0) -> 0.220672 | G28: =_xlfn.IFERROR(IF((G27/'Notes A&B - Revenue & COGS'!H24)<0,0,(G27/'Notes A&B - Revenue & COGS'!H24)),0) -> 0.21488021 | H28: =_xlfn.IFERROR(IF((H27/'Notes A&B - Revenue & COGS'!I24)<0,0,(H27/'Notes A&B - Revenue & COGS'!I24)),0) -> 0.20941449 | I28: =_xlfn.IFERROR(IF((I27/'Notes A&B - Revenue & COGS'!J24)<0,0,(I27/'Notes A&B - Revenue & COGS'!J24)),0) -> 0.20424806 | J28: =_xlfn.IFERROR(IF((J27/'Notes A&B - Revenue & COGS'!K24)<0,0,(J27/'Notes A&B - Revenue & COGS'!K24)),0) -> 0.19633722 | K28: =_xlfn.IFERROR(IF((K27/'Notes A&B - Revenue & COGS'!L24)<0,0,(K27/'Notes A&B - Revenue & COGS'!L24)),0) -> 0.19185185 | ... T28: =_xlfn.IFERROR(IF((T27/'Notes A&B - Revenue & COGS'!U24)<0,0,(T27/'Notes A&B - Revenue & COGS'!U24)),0) -> 0.18366057
B30: Employee Assumptions | C30: Hourly Pay
A31: 1 | B31: ='Key Assumptions & Drivers'!B72 -> Site Manager | C31: ='Key Assumptions & Drivers'!$E$72 -> 30 | D31: 0 | E31: =$C$33*$C$31/12 -> 5200 | F31: =$C$33*$C$31/12 -> 5200 | G31: =$C$33*$C$31/12 -> 5200 | H31: =$C$33*$C$31/12 -> 5200 | I31: =$C$33*$C$31/12 -> 5200 | J31: =$C$33*$C$31/12 -> 5200 | K31: =$C$33*$C$31/12 -> 5200 | L31: =$C$33*$C$31/12 -> 5200 | ... O31: =$C$33*$C$31/12 -> 5200 | P31: =SUM(D31:O31) -> 57200 | Q31: =(C31*C33)*(1+Q32) -> 66144 | R31: =Q31*(1+R32) -> 70112.64 | S31: =R31*(1+S32) -> 74319.398 | T31: =S31*(1+T32) -> 78778.562
B32: Raise | C32: Chg @ T35 | Q32: ='Key Assumptions & Drivers'!G$72 -> 0.06 | R32: ='Key Assumptions & Drivers'!H$72 -> 0.06 | S32: ='Key Assumptions & Drivers'!I$72 -> 0.06 | T32: ='Key Assumptions & Drivers'!J$72 -> 0.06
B33: Hours/Year | C33: ='Key Assumptions & Drivers'!$F$72 -> 2080
A34: 2 | B34: ='Key Assumptions & Drivers'!B73 -> Part Time | C34: ='Key Assumptions & Drivers'!$E$73 -> 16 | D34: 0 | E34: =$C$36*$C$34/12 -> 2773.3333 | F34: =$C$36*$C$34/12 -> 2773.3333 | G34: =$C$36*$C$34/12 -> 2773.3333 | H34: =$C$36*$C$34/12 -> 2773.3333 | I34: =$C$36*$C$34/12 -> 2773.3333 | J34: =$C$36*$C$34/12 -> 2773.3333 | K34: =$C$36*$C$34/12 -> 2773.3333 | L34: =$C$36*$C$34/12 -> 2773.3333 | ... O34: =$C$36*$C$34/12 -> 2773.3333 | P34: =SUM(D34:O34) -> 30506.667 | Q34: =(C34*C36)*(1+Q35) -> 35276.8 | R34: =Q34*(1+R35) -> 37393.408 | S34: =R34*(1+S35) -> 39637.012 | T34: =S34*(1+T35) -> 42015.233
B35: Raise | C35: Chg @ T38 | Q35: ='Key Assumptions & Drivers'!G$73 -> 0.06 | R35: ='Key Assumptions & Drivers'!H$73 -> 0.06 | S35: ='Key Assumptions & Drivers'!I$73 -> 0.06 | T35: ='Key Assumptions & Drivers'!J$73 -> 0.06
B36: Hours/Year | C36: ='Key Assumptions & Drivers'!$F$73 -> 2080
A37: 3 | B37: ='Key Assumptions & Drivers'!B74 -> Full Time | C37: ='Key Assumptions & Drivers'!$E$74 -> 16 | D37: 0 | E37: =$C$39*$C$37/12 -> 2773.3333 | F37: =$C$39*$C$37/12 -> 2773.3333 | G37: =$C$39*$C$37/12 -> 2773.3333 | H37: =$C$39*$C$37/12 -> 2773.3333 | I37: =$C$39*$C$37/12 -> 2773.3333 | J37: =$C$39*$C$37/12 -> 2773.3333 | K37: =$C$39*$C$37/12 -> 2773.3333 | L37: =$C$39*$C$37/12 -> 2773.3333 | ... O37: =$C$39*$C$37/12 -> 2773.3333 | P37: =SUM(D37:O37) -> 30506.667 | Q37: =(C37*C39)*(1+Q38) -> 36608 | R37: =Q37*(1+R38) -> 40268.8 | S37: =R37*(1+S38) -> 44295.68 | T37: =S37*(1+T38) -> 48725.248
B38: Raise | C38: Chg @ T41 | Q38: ='Key Assumptions & Drivers'!G$74 -> 0.1 | R38: ='Key Assumptions & Drivers'!H$74 -> 0.1 | S38: ='Key Assumptions & Drivers'!I$74 -> 0.1 | T38: ='Key Assumptions & Drivers'!J$74 -> 0.1
B39: Hours/Year | C39: ='Key Assumptions & Drivers'!$F$74 -> 2080
A40: 4 | B40: ='Key Assumptions & Drivers'!B75 -> Full Time | C40: ='Key Assumptions & Drivers'!$E$75 -> 16 | D40: 0 | E40: =$C$42*$C$40/12 -> 2773.3333 | F40: =$C$42*$C$40/12 -> 2773.3333 | G40: =$C$42*$C$40/12 -> 2773.3333 | H40: =$C$42*$C$40/12 -> 2773.3333 | I40: =$C$42*$C$40/12 -> 2773.3333 | J40: =$C$42*$C$40/12 -> 2773.3333 | K40: =$C$42*$C$40/12 -> 2773.3333 | L40: =$C$42*$C$40/12 -> 2773.3333 | ... O40: =$C$42*$C$40/12 -> 2773.3333 | P40: =SUM(D40:O40) -> 30506.667 | Q40: =(C40*C42)*(1+Q41) -> 36608 | R40: =Q40*(1+R41) -> 40268.8 | S40: =R40*(1+S41) -> 44295.68 | T40: =S40*(1+T41) -> 48725.248
B41: Raise | C41: Chg @ T44 | Q41: ='Key Assumptions & Drivers'!G$75 -> 0.1 | R41: ='Key Assumptions & Drivers'!H$75 -> 0.1 | S41: ='Key Assumptions & Drivers'!I$75 -> 0.1 | T41: ='Key Assumptions & Drivers'!J$75 -> 0.1
B42: Hours/Year | C42: ='Key Assumptions & Drivers'!$F$75 -> 2080
B43: TOTAL | D43: =SUM(D31,D34,D37,D40) -> 0 | E43: =SUM(E31,E34,E37,E40) -> 13520 | F43: =SUM(F31,F34,F37,F40) -> 13520 | G43: =SUM(G31,G34,G37,G40) -> 13520 | H43: =SUM(H31,H34,H37,H40) -> 13520 | I43: =SUM(I31,I34,I37,I40) -> 13520 | J43: =SUM(J31,J34,J37,J40) -> 13520 | K43: =SUM(K31,K34,K37,K40) -> 13520 | ... O43: =SUM(O31,O34,O37,O40) -> 13520 | P43: =SUM(D43:O43) -> 148720 | Q43: =SUM(Q31,Q34,Q37,Q40) -> 174636.8 | R43: =SUM(R31,R34,R37,R40) -> 188043.65 | S43: =SUM(S31,S34,S37,S40) -> 202547.77 | T43: =SUM(T31,T34,T37,T40) -> 218244.29
B46: Check | F46: =F9+'Note F - Other analysis'!G29 -> 13520 | G46: =G9+'Note F - Other analysis'!H29 -> 13520 | H46: =H9+'Note F - Other analysis'!I29 -> 13520 | I46: =I9+'Note F - Other analysis'!J29 -> 13520 | J46: =J9+'Note F - Other analysis'!K29 -> 13520 | K46: =K9+'Note F - Other analysis'!L29 -> 13520 | L46: =L9+'Note F - Other analysis'!M29 -> 13520 | M46: =M9+'Note F - Other analysis'!N29 -> 13520 | ... T46: =T9+'Note F - Other analysis'!U29 -> 218244.29

Sheet Note D - PPE
B2: NOTE D TO FINANCIAL STATEMENTS
B6: PPE | D6: 6 Months
C7: Note | D7: Construction | E7: 43313 | F7: 43344 | G7: 43374 | H7: 43405 | I7: 43435 | J7: 43466 | K7: 43497 | L7: 43525 | M7: 43556 | N7: 43586 | O7: 43617 | P7: Year 1 | Q7: 43983 | R7: 44348 | S7: 44713 | T7: 45078
D8: (est.) | E8: (est.) | F8: (est.) | G8: (est.) | H8: (est.) | I8: (est.) | J8: (est.) | K8: (est.) | L8: (est.) | M8: (est.) | N8: (est.) | O8: (est.) | P8: (est.) | Q8: (est.) | R8: (est.) | S8: (est.) | T8: (est.)
B10: CAPEX
B11: Land Value Per Books | D11: =C48 -> 875000 | E11: =D11 -> 875000 | F11: =E11 -> 875000 | G11: =F11 -> 875000 | H11: =G11 -> 875000 | I11: =H11 -> 875000 | J11: =I11 -> 875000 | K11: =J11 -> 875000 | L11: =K11 -> 875000 | ... T11: =S11 -> 875000
B12: City Fees | D12: =C49 -> 250000 | E12: =D12 -> 250000 | F12: =E12 -> 250000 | G12: =F12 -> 250000 | H12: =G12 -> 250000 | I12: =H12 -> 250000 | J12: =I12 -> 250000 | K12: =J12 -> 250000 | L12: =K12 -> 250000 | ... T12: =S12 -> 250000
D13: =SUM(D11:D12) -> 1125000 | E13: =SUM(E11:E12) -> 1125000 | F13: =SUM(F11:F12) -> 1125000 | G13: =SUM(G11:G12) -> 1125000 | H13: =SUM(H11:H12) -> 1125000 | I13: =SUM(I11:I12) -> 1125000 | J13: =SUM(J11:J12) -> 1125000 | K13: =SUM(K11:K12) -> 1125000 | ... T13: =SUM(T11:T12) -> 1125000
B14: Land Value Per City | D14: =D11 -> 875000 | E14: =E11 -> 875000 | F14: =F11 -> 875000 | G14: =G11 -> 875000 | H14: =H11 -> 875000 | I14: =I11 -> 875000 | J14: =J11 -> 875000 | K14: =K11 -> 875000 | ... P14: =P11 -> 875000 | Q14: =P14*(1+'Key Assumptions & Drivers'!$D$89) -> 892500 | R14: =Q14*(1+'Key Assumptions & Drivers'!$D$89) -> 910350 | S14: =R14*(1+'Key Assumptions & Drivers'!$D$89) -> 928557 | T14: =S14*(1+'Key Assumptions & Drivers'!$D$89) -> 947128.14
B16: Building | D16: =$C$50 -> 150000 | E16: =$C$50 -> 150000 | F16: =E16 -> 150000 | G16: =F16 -> 150000 | H16: =G16 -> 150000 | I16: =H16 -> 150000 | J16: =I16 -> 150000 | K16: =J16 -> 150000 | L16: =K16 -> 150000 | M16: =L16 -> 150000 | ... T16: =S16 -> 150000
B17: Car Wash Equipment | D17: =$C$51 -> 1200000 | E17: =$C$51 -> 1200000 | F17: =E17 -> 1200000 | G17: =F17 -> 1200000 | H17: =G17 -> 1200000 | I17: =H17 -> 1200000 | J17: =I17 -> 1200000 | K17: =J17 -> 1200000 | L17: =K17 -> 1200000 | M17: =L17 -> 1200000 | ... T17: =S17 -> 1200000
B18: Construction Site | D18: =C52 -> 1080000 | E18: =D18 -> 1080000 | F18: =E18 -> 1080000 | G18: =F18 -> 1080000 | H18: =G18 -> 1080000 | I18: =H18 -> 1080000 | J18: =I18 -> 1080000 | K18: =J18 -> 1080000 | L18: =K18 -> 1080000 | ... T18: =S18 -> 1080000
B19: Contingency Cushion | D19: =C53 -> 108000 | E19: =D19 -> 108000 | F19: =E19 -> 108000 | G19: =F19 -> 108000 | H19: =G19 -> 108000 | I19: =H19 -> 108000 | J19: =I19 -> 108000 | K19: =J19 -> 108000 | L19: =K19 -> 108000 | ... T19: =S19 -> 108000
E20: =D20 -> 0 | F20: =E20 -> 0 | G20: =F20 -> 0 | H20: =G20 -> 0 | I20: =H20 -> 0 | J20: =I20 -> 0 | K20: =J20 -> 0 | L20: =K20 -> 0 | ... T20: =S20 -> 0
D21: =SUM(D16:D20) -> 2538000 | E21: =SUM(E16:E20) -> 2538000 | F21: =SUM(F16:F20) -> 2538000 | G21: =SUM(G16:G20) -> 2538000 | H21: =SUM(H16:H20) -> 2538000 | I21: =SUM(I16:I20) -> 2538000 | J21: =SUM(J16:J20) -> 2538000 | K21: =SUM(K16:K20) -> 2538000 | ... T21: =SUM(T16:T20) -> 2538000
C23: Total | D23: =D21+D13 -> 3663000 | E23: =E21+E13 -> 3663000 | F23: =F21+F13 -> 3663000 | G23: =G21+G13 -> 3663000 | H23: =H21+H13 -> 3663000 | I23: =I21+I13 -> 3663000 | J23: =J21+J13 -> 3663000 | K23: =K21+K13 -> 3663000 | ... T23: =T21+T13 -> 3663000
